<?xml version="1.0" encoding="utf-8"?>
<!-- This URDF was automatically created by SolidWorks to URDF Exporter! Originally created by Stephen Brawner (brawner@gmail.com) 
     Commit Version: 1.6.0-1-g15f4949  Build Version: 1.6.7594.29634
     For more information, please see http://wiki.ros.org/sw_urdf_exporter -->
<robot
  name="adeep_urdf.SLDASM">
  <link
    name="base_link">
    <inertial>
      <origin
        xyz="1.44778816202133E-18 0.0395704194819336 3.00046906199441E-19"
        rpy="0 0 0" />
      <mass
        value="1.17010619298297" />
      <inertia
        ixx="0.00214835309114068"
        ixy="-3.44517326982493E-21"
        ixz="-3.97046694025453E-20"
        iyy="0.00288931099532631"
        iyz="2.1108504443776E-20"
        izz="0.00199296884881658" />
    </inertial>
    <visual>
      <origin
        xyz="0 0 0"
        rpy="0 0 0" />
      <geometry>
        <mesh
          filename="package://adeep_urdf.SLDASM/meshes/base_link.STL" />
      </geometry>
      <material
        name="">
        <color
          rgba="1 0 0 1" />
      </material>
    </visual>
    <collision>
      <origin
        xyz="0 0 0"
        rpy="0 0 0" />
      <geometry>
        <mesh
          filename="package://adeep_urdf.SLDASM/meshes/base_link.STL" />
      </geometry>
    </collision>
  </link>
  <link
    name="camera">
    <inertial>
      <origin
        xyz="1.783E-19 0.02 0"
        rpy="0 0 0" />
      <mass
        value="0.04" />
      <inertia
        ixx="6.6667E-06"
        ixy="4.9749E-22"
        ixz="8.0694E-23"
        iyy="9.6667E-06"
        iyz="1.7647E-22"
        izz="1.3667E-05" />
    </inertial>
    <visual>
      <origin
        xyz="0 0 0"
        rpy="0 0 0" />
      <geometry>
        <mesh
          filename="package://adeep_urdf.SLDASM/meshes/camera.STL" />
      </geometry>
      <material
        name="">
        <color
          rgba="0.79216 0.81961 0.93333 1" />
      </material>
    </visual>
    <collision>
      <origin
        xyz="0 0 0"
        rpy="0 0 0" />
      <geometry>
        <mesh
          filename="package://adeep_urdf.SLDASM/meshes/camera.STL" />
      </geometry>
    </collision>
  </link>
  <joint
    name="camera_joint"
    type="fixed">
    <origin
      xyz="0 -0.0725 0.04"
      rpy="1.5708 0 0" />
    <parent
      link="base_link" />
    <child
      link="camera" />
    <axis
      xyz="0 0 0" />
  </joint>
  <link
    name="ultrasonic">
    <inertial>
      <origin
        xyz="6.6174E-19 0.01 0"
        rpy="0 0 0" />
      <mass
        value="0.02" />
      <inertia
        ixx="1.3333E-06"
        ixy="-8.8233E-23"
        ixz="4.3312E-23"
        iyy="4.8333E-06"
        iyz="-5.2042E-23"
        izz="4.8333E-06" />
    </inertial>
    <visual>
      <origin
        xyz="0 0 0"
        rpy="0 0 0" />
      <geometry>
        <mesh
          filename="package://adeep_urdf.SLDASM/meshes/ultrasonic.STL" />
      </geometry>
      <material
        name="">
        <color
          rgba="0 0 1 1" />
      </material>
    </visual>
    <collision>
      <origin
        xyz="0 0 0"
        rpy="0 0 0" />
      <geometry>
        <mesh
          filename="package://adeep_urdf.SLDASM/meshes/ultrasonic.STL" />
      </geometry>
    </collision>
  </link>
  <joint
    name="ultrasonic_joint"
    type="fixed">
    <origin
      xyz="0 -0.0725 0.01"
      rpy="1.5708 0 0" />
    <parent
      link="base_link" />
    <child
      link="ultrasonic" />
    <axis
      xyz="0 0 0" />
  </joint>
  <link
    name="left_front_wheel">
    <inertial>
      <origin
        xyz="-0.0125 1.73472347597681E-17 2.08166817117217E-17"
        rpy="0 0 0" />
      <mass
        value="0.0805033117482385" />
      <inertia
        ixx="4.64101592228595E-05"
        ixy="-1.01933421967495E-23"
        ixz="3.04396514226628E-21"
        iyy="2.73979604316505E-05"
        iyz="1.6940658945086E-21"
        izz="2.73979604316505E-05" />
    </inertial>
    <visual>
      <origin
        xyz="0 0 0"
        rpy="0 0 0" />
      <geometry>
        <mesh
          filename="package://adeep_urdf.SLDASM/meshes/left_front_wheel.STL" />
      </geometry>
      <material
        name="">
        <color
          rgba="0.203921568627451 0.203921568627451 0.203921568627451 1" />
      </material>
    </visual>
    <collision>
      <origin
        xyz="0 0 0"
        rpy="0 0 0" />
      <geometry>
        <mesh
          filename="package://adeep_urdf.SLDASM/meshes/left_front_wheel.STL" />
      </geometry>
    </collision>
  </link>
  <joint
    name="left_front_wheel_joint"
    type="continuous">
    <origin
      xyz="0.0575 -0.035 0.015"
      rpy="2.7498 0 -3.1416" />
    <parent
      link="base_link" />
    <child
      link="left_front_wheel" />
    <axis
      xyz="1 0 0" />
  </joint>
  <link
    name="left_rear_wheel">
    <inertial>
      <origin
        xyz="0.0125 0 0"
        rpy="0 0 0" />
      <mass
        value="0.0805033117482385" />
      <inertia
        ixx="4.64101592228595E-05"
        ixy="-7.21864153626838E-38"
        ixz="-3.92778894867577E-37"
        iyy="2.73979604316505E-05"
        iyz="-6.14301606978348E-40"
        izz="2.73979604316505E-05" />
    </inertial>
    <visual>
      <origin
        xyz="0 0 0"
        rpy="0 0 0" />
      <geometry>
        <mesh
          filename="package://adeep_urdf.SLDASM/meshes/left_rear_wheel.STL" />
      </geometry>
      <material
        name="">
        <color
          rgba="0.203921568627451 0.203921568627451 0.203921568627451 1" />
      </material>
    </visual>
    <collision>
      <origin
        xyz="0 0 0"
        rpy="0 0 0" />
      <geometry>
        <mesh
          filename="package://adeep_urdf.SLDASM/meshes/left_rear_wheel.STL" />
      </geometry>
    </collision>
  </link>
  <joint
    name="left_rear_wheel_joint"
    type="continuous">
    <origin
      xyz="0.0575 0.035 0.015"
      rpy="1.5708 0 0" />
    <parent
      link="base_link" />
    <child
      link="left_rear_wheel" />
    <axis
      xyz="1 0 0" />
  </joint>
  <link
    name="right_front_wheel">
    <inertial>
      <origin
        xyz="0.0125 3.46944695195361E-18 2.42861286636753E-17"
        rpy="0 0 0" />
      <mass
        value="0.0805033117482385" />
      <inertia
        ixx="4.64101592228595E-05"
        ixy="-1.01933421967497E-23"
        ixz="3.04396514226628E-21"
        iyy="2.73979604316505E-05"
        iyz="2.5410988417629E-21"
        izz="2.73979604316505E-05" />
    </inertial>
    <visual>
      <origin
        xyz="0 0 0"
        rpy="0 0 0" />
      <geometry>
        <mesh
          filename="package://adeep_urdf.SLDASM/meshes/right_front_wheel.STL" />
      </geometry>
      <material
        name="">
        <color
          rgba="0.203921568627451 0.203921568627451 0.203921568627451 1" />
      </material>
    </visual>
    <collision>
      <origin
        xyz="0 0 0"
        rpy="0 0 0" />
      <geometry>
        <mesh
          filename="package://adeep_urdf.SLDASM/meshes/right_front_wheel.STL" />
      </geometry>
    </collision>
  </link>
  <joint
    name="right_front_wheel_joint"
    type="continuous">
    <origin
      xyz="-0.0575 -0.035 0.015"
      rpy="2.7498 0 -3.1416" />
    <parent
      link="base_link" />
    <child
      link="right_front_wheel" />
    <axis
      xyz="1 0 0" />
  </joint>
  <link
    name="right_rear_wheel">
    <inertial>
      <origin
        xyz="0.0125 -2.08166817117217E-17 -3.46944695195361E-17"
        rpy="0 0 0" />
      <mass
        value="0.0805033117482385" />
      <inertia
        ixx="4.64101592228595E-05"
        ixy="-1.01933421967498E-23"
        ixz="3.04396514226628E-21"
        iyy="2.73979604316505E-05"
        iyz="2.5410988417629E-21"
        izz="2.73979604316505E-05" />
    </inertial>
    <visual>
      <origin
        xyz="0 0 0"
        rpy="0 0 0" />
      <geometry>
        <mesh
          filename="package://adeep_urdf.SLDASM/meshes/right_rear_wheel.STL" />
      </geometry>
      <material
        name="">
        <color
          rgba="0.203921568627451 0.203921568627451 0.203921568627451 1" />
      </material>
    </visual>
    <collision>
      <origin
        xyz="0 0 0"
        rpy="0 0 0" />
      <geometry>
        <mesh
          filename="package://adeep_urdf.SLDASM/meshes/right_rear_wheel.STL" />
      </geometry>
    </collision>
  </link>
  <joint
    name="right_rear_wheel_joint"
    type="continuous">
    <origin
      xyz="-0.0575 0.035 0.015"
      rpy="2.7498 0 -3.1416" />
    <parent
      link="base_link" />
    <child
      link="right_rear_wheel" />
    <axis
      xyz="1 0 0" />
  </joint>
</robot>