<?xml version="1.0" ?>
<!-- =================================================================================== -->
<!-- |    This document was autogenerated by xacro from /home/pi/ros2_ws_forpc/src/simple_bot/urdf/simple_bot.xacro | -->
<!-- |    EDITING THIS FILE BY HAND IS NOT RECOMMENDED                                 | -->
<!-- =================================================================================== -->
<robot name="simple_bot">
  <material name="gray">
    <color rgba="0.5 0.5 0.5 1"/>
  </material>
  <material name="black">
    <color rgba="0 0 0 1"/>
  </material>
  <material name="blue">
    <color rgba="0 0 1 1"/>
  </material>
  <material name="red">
    <color rgba="1 0 0 1"/>
  </material>
  <!-- 기본 몸체 -->
  <link name="base_link">
    <visual>
      <geometry>
        <box size="0.3 0.2 0.1"/>
      </geometry>
      <material name="gray"/>
    </visual>
  </link>
  <!-- 왼쪽 바퀴 -->
  <link name="left_wheel">
    <visual>
      <geometry>
        <cylinder length="0.03" radius="0.05"/>
      </geometry>
      <material name="black"/>
    </visual>
  </link>
  <!-- 오른쪽 바퀴 -->
  <link name="right_wheel">
    <visual>
      <geometry>
        <cylinder length="0.03" radius="0.05"/>
      </geometry>
      <material name="black"/>
    </visual>
  </link>
  <!-- 카메라 -->
  <link name="camera_link">
    <visual>
      <geometry>
        <box size="0.04 0.04 0.04"/>
      </geometry>
      <material name="blue"/>
    </visual>
  </link>
  <!-- 초음파 센서 -->
  <link name="ultrasonic_link">
    <visual>
      <geometry>
        <cylinder length="0.02" radius="0.02"/>
      </geometry>
      <material name="red"/>
    </visual>
  </link>
  <!-- 조인트 -->
  <joint name="left_wheel_joint" type="continuous">
    <parent link="base_link"/>
    <child link="left_wheel"/>
    <origin xyz="0 0.12 0"/>
    <axis xyz="0 1 0"/>
  </joint>
  <joint name="right_wheel_joint" type="continuous">
    <parent link="base_link"/>
    <child link="right_wheel"/>
    <origin xyz="0 -0.12 0"/>
    <axis xyz="0 1 0"/>
  </joint>
  <joint name="camera_joint" type="fixed">
    <parent link="base_link"/>
    <child link="camera_link"/>
    <origin xyz="0.1 0 0.1"/>
  </joint>
  <joint name="ultrasonic_joint" type="fixed">
    <parent link="base_link"/>
    <child link="ultrasonic_link"/>
    <origin xyz="0.15 0 0.05"/>
  </joint>
  <!-- Gazebo 플러그인: 차륜 구동 -->
  <gazebo>
    <plugin filename="libgazebo_ros_diff_drive.so" name="diff_drive">
      <ros>
        <namespace>/simple_bot</namespace>
      </ros>
      <update_rate>50.0</update_rate>
      <left_joint>left_wheel_joint</left_joint>
      <right_joint>right_wheel_joint</right_joint>
      <wheel_separation>0.24</wheel_separation>
      <wheel_diameter>0.1</wheel_diameter>
      <command_topic>cmd_vel</command_topic>
      <odometry_topic>odom</odometry_topic>
      <publish_odom>true</publish_odom>
    </plugin>
  </gazebo>
  <!-- Gazebo 카메라 -->
  <gazebo reference="camera_link">
    <sensor name="camera_sensor" type="camera">
      <update_rate>30.0</update_rate>
      <camera name="head_camera">
        <horizontal_fov>1.3962634</horizontal_fov>
        <image>
          <width>640</width>
          <height>480</height>
          <format>R8G8B8</format>
        </image>
        <clip>
          <near>0.05</near>
          <far>50</far>
        </clip>
      </camera>
      <plugin filename="libgazebo_ros_camera.so" name="camera_controller">
        <ros>
          <namespace>/simple_bot</namespace>
          <argument>camera_info_url</argument>
        </ros>
        <camera_name>camera</camera_name>
        <frame_name>camera_link</frame_name>
      </plugin>
    </sensor>
  </gazebo>
  <!-- Gazebo 초음파 -->
  <gazebo reference="ultrasonic_link">
    <sensor name="ultrasonic_sensor" type="ray">
      <update_rate>10.0</update_rate>
      <ray>
        <scan>
          <horizontal>
            <samples>5</samples>
            <resolution>1</resolution>
            <min_angle>-0.1</min_angle>
            <max_angle>0.1</max_angle>
          </horizontal>
        </scan>
        <range>
          <min>0.02</min>
          <max>2.0</max>
          <resolution>0.01</resolution>
        </range>
      </ray>
      <plugin filename="libgazebo_ros_ray_sensor.so" name="ultrasonic_controller">
        <ros>
          <namespace>/simple_bot</namespace>
        </ros>
        <frame_name>ultrasonic_link</frame_name>
      </plugin>
    </sensor>
  </gazebo>
</robot>
