<?xml version="1.0" ?>
<!-- =================================================================================== -->
<!-- |    This document was autogenerated by xacro from /home/pi/ros2_ws_forpc/src/simple_bot/urdf/simple_bot.xacro | -->
<!-- |    EDITING THIS FILE BY HAND IS NOT RECOMMENDED                                 | -->
<!-- =================================================================================== -->
<robot name="simple_bot">
  <!-- 앞뒤 바퀴 간격 -->
  <!-- ===================== base_link ===================== -->
  <link name="base_link">
    <visual>
      <geometry>
        <box size="0.125 0.115 0.08"/>
      </geometry>
      <origin rpy="0 0 0" xyz="0 0 0.04"/>
      <material name="Gray">
        <color rgba="0.6 0.6 0.6 1.0"/>
      </material>
    </visual>
    <collision>
      <geometry>
        <box size="0.125 0.115 0.08"/>
      </geometry>
    </collision>
  </link>
  <!-- ===================== Left Wheels ===================== -->
  <!-- Left Front Wheel -->
  <link name="left_front_wheel_link">
    <visual>
      <geometry>
        <cylinder length="0.025" radius="0.033"/>
      </geometry>
      <origin rpy="1.5708 0 0" xyz="0 0 0"/>
      <material name="Black">
        <color rgba="0 0 0 1"/>
      </material>
    </visual>
  </link>
  <joint name="left_front_wheel_joint" type="continuous">
    <parent link="base_link"/>
    <child link="left_front_wheel_link"/>
    <origin rpy="0 0 0" xyz="0.04 0.07 0.033"/>
    <axis xyz="0 1 0"/>
  </joint>
  <!-- Left Rear Wheel -->
  <link name="left_rear_wheel_link">
    <visual>
      <geometry>
        <cylinder length="0.025" radius="0.033"/>
      </geometry>
      <origin rpy="1.5708 0 0" xyz="0 0 0"/>
      <material name="Black">
        <color rgba="0 0 0 1"/>
      </material>
    </visual>
  </link>
  <joint name="left_rear_wheel_joint" type="continuous">
    <parent link="base_link"/>
    <child link="left_rear_wheel_link"/>
    <origin rpy="0 0 0" xyz="-0.04 0.07 0.033"/>
    <axis xyz="0 1 0"/>
  </joint>
  <!-- ===================== Right Wheels ===================== -->
  <!-- Right Front Wheel -->
  <link name="right_front_wheel_link">
    <visual>
      <geometry>
        <cylinder length="0.025" radius="0.033"/>
      </geometry>
      <origin rpy="1.5708 0 0" xyz="0 0 0"/>
      <material name="Black">
        <color rgba="0 0 0 1"/>
      </material>
    </visual>
  </link>
  <joint name="right_front_wheel_joint" type="continuous">
    <parent link="base_link"/>
    <child link="right_front_wheel_link"/>
    <origin rpy="0 0 0" xyz="0.04 -0.07 0.033"/>
    <axis xyz="0 1 0"/>
  </joint>
  <!-- Right Rear Wheel -->
  <link name="right_rear_wheel_link">
    <visual>
      <geometry>
        <cylinder length="0.025" radius="0.033"/>
      </geometry>
      <origin rpy="1.5708 0 0" xyz="0 0 0"/>
      <material name="Black">
        <color rgba="0 0 0 1"/>
      </material>
    </visual>
  </link>
  <joint name="right_rear_wheel_joint" type="continuous">
    <parent link="base_link"/>
    <child link="right_rear_wheel_link"/>
    <origin rpy="0 0 0" xyz="-0.04 -0.07 0.033"/>
    <axis xyz="0 1 0"/>
  </joint>
  <!-- ===================== Ultrasonic Sensor ===================== -->
  <link name="ultrasonic_link">
    <visual>
      <geometry>
        <box size="0.02 0.05 0.02"/>
      </geometry>
      <origin rpy="0 0 0" xyz="0.0725 0 0.02"/>
      <material name="Yellow">
        <color rgba="1.0 1.0 0.0 1.0"/>
      </material>
    </visual>
  </link>
  <joint name="ultrasonic_link" type="fixed">
    <parent link="base_link"/>
    <child link="ultrasonic_link"/>
    <origin rpy="0 0 0" xyz="0 0 0"/>
  </joint>
  <!-- ===================== Camera ===================== -->
  <link name="camera_link">
    <visual>
      <geometry>
        <box size="0.02 0.05 0.04"/>
      </geometry>
      <origin rpy="0 0 0" xyz="0.0725 0 0.055999999999999994"/>
      <material name="Red">
        <color rgba="1.0 0.0 0.0 1.0"/>
      </material>
    </visual>
  </link>
  <joint name="camera_joint" type="fixed">
    <parent link="base_link"/>
    <child link="camera_link"/>
    <origin rpy="0 0 0" xyz="0 0 0"/>
  </joint>
</robot>
