<sdf version='1.7'>
  <model name='simple_bot'>
    <link name='base_link'>
      <inertial>
        <pose>0 0 0 0 -0 0</pose>
        <mass>1</mass>
        <inertia>
          <ixx>0.001</ixx>
          <ixy>0</ixy>
          <ixz>0</ixz>
          <iyy>0.001</iyy>
          <iyz>0</iyz>
          <izz>0.001</izz>
        </inertia>
      </inertial>
      <collision name='base_link_collision'>
        <pose>0 0 0.073 0 -0 0</pose>
        <geometry>
          <box>
            <size>0.125 0.115 0.08</size>
          </box>
        </geometry>
      </collision>
      <visual name='base_link_visual'>
        <pose>0 0 0.073 0 -0 0</pose>
        <geometry>
          <box>
            <size>0.125 0.115 0.08</size>
          </box>
        </geometry>
      </visual>
      <visual name='base_link_fixed_joint_lump__camera_link_visual_1'>
        <pose>0.0725 0 0.076 0 -0 0</pose>
        <geometry>
          <box>
            <size>0.02 0.05 0.04</size>
          </box>
        </geometry>
      </visual>
      <visual name='base_link_fixed_joint_lump__ultrasonic_link_visual_2'>
        <pose>0.0725 0 0.04 0 -0 0</pose>
        <geometry>
          <box>
            <size>0.02 0.05 0.02</size>
          </box>
        </geometry>
      </visual>
    </link>
    <joint name='left_front_wheel_joint' type='revolute'>
      <pose relative_to='base_link'>0.04 0.07 0.033 0 -0 0</pose>
      <parent>base_link</parent>
      <child>left_front_wheel_link</child>
      <axis>
        <xyz>0 1 0</xyz>
        <limit>
          <lower>-1e+16</lower>
          <upper>1e+16</upper>
        </limit>
        <dynamics>
          <spring_reference>0</spring_reference>
          <spring_stiffness>0</spring_stiffness>
        </dynamics>
      </axis>
    </joint>
    <link name='left_front_wheel_link'>
      <pose relative_to='left_front_wheel_joint'>0 0 0 0 -0 0</pose>
      <inertial>
        <pose>0 0 0 0 -0 0</pose>
        <mass>0.2</mass>
        <inertia>
          <ixx>5.6e-05</ixx>
          <ixy>0</ixy>
          <ixz>0</ixz>
          <iyy>5.6e-05</iyy>
          <iyz>0</iyz>
          <izz>9e-05</izz>
        </inertia>
      </inertial>
      <collision name='left_front_wheel_link_collision'>
        <pose>0 0 0 1.5708 -0 0</pose>
        <geometry>
          <cylinder>
            <length>0.025</length>
            <radius>0.033</radius>
          </cylinder>
        </geometry>
      </collision>
      <visual name='left_front_wheel_link_visual'>
        <pose>0 0 0 1.5708 -0 0</pose>
        <geometry>
          <cylinder>
            <length>0.025</length>
            <radius>0.033</radius>
          </cylinder>
        </geometry>
      </visual>
    </link>
    <joint name='left_rear_wheel_joint' type='revolute'>
      <pose relative_to='base_link'>-0.04 0.07 0.033 0 -0 0</pose>
      <parent>base_link</parent>
      <child>left_rear_wheel_link</child>
      <axis>
        <xyz>0 1 0</xyz>
        <limit>
          <lower>-1e+16</lower>
          <upper>1e+16</upper>
        </limit>
        <dynamics>
          <spring_reference>0</spring_reference>
          <spring_stiffness>0</spring_stiffness>
        </dynamics>
      </axis>
    </joint>
    <link name='left_rear_wheel_link'>
      <pose relative_to='left_rear_wheel_joint'>0 0 0 0 -0 0</pose>
      <inertial>
        <pose>0 0 0 0 -0 0</pose>
        <mass>0.2</mass>
        <inertia>
          <ixx>5.6e-05</ixx>
          <ixy>0</ixy>
          <ixz>0</ixz>
          <iyy>5.6e-05</iyy>
          <iyz>0</iyz>
          <izz>9e-05</izz>
        </inertia>
      </inertial>
      <collision name='left_rear_wheel_link_collision'>
        <pose>0 0 0 1.5708 -0 0</pose>
        <geometry>
          <cylinder>
            <length>0.025</length>
            <radius>0.033</radius>
          </cylinder>
        </geometry>
      </collision>
      <visual name='left_rear_wheel_link_visual'>
        <pose>0 0 0 1.5708 -0 0</pose>
        <geometry>
          <cylinder>
            <length>0.025</length>
            <radius>0.033</radius>
          </cylinder>
        </geometry>
      </visual>
    </link>
    <joint name='right_front_wheel_joint' type='revolute'>
      <pose relative_to='base_link'>0.04 -0.07 0.033 0 -0 0</pose>
      <parent>base_link</parent>
      <child>right_front_wheel_link</child>
      <axis>
        <xyz>0 1 0</xyz>
        <limit>
          <lower>-1e+16</lower>
          <upper>1e+16</upper>
        </limit>
        <dynamics>
          <spring_reference>0</spring_reference>
          <spring_stiffness>0</spring_stiffness>
        </dynamics>
      </axis>
    </joint>
    <link name='right_front_wheel_link'>
      <pose relative_to='right_front_wheel_joint'>0 0 0 0 -0 0</pose>
      <inertial>
        <pose>0 0 0 0 -0 0</pose>
        <mass>0.2</mass>
        <inertia>
          <ixx>5.6e-05</ixx>
          <ixy>0</ixy>
          <ixz>0</ixz>
          <iyy>5.6e-05</iyy>
          <iyz>0</iyz>
          <izz>9e-05</izz>
        </inertia>
      </inertial>
      <collision name='right_front_wheel_link_collision'>
        <pose>0 0 0 1.5708 -0 0</pose>
        <geometry>
          <cylinder>
            <length>0.025</length>
            <radius>0.033</radius>
          </cylinder>
        </geometry>
      </collision>
      <visual name='right_front_wheel_link_visual'>
        <pose>0 0 0 1.5708 -0 0</pose>
        <geometry>
          <cylinder>
            <length>0.025</length>
            <radius>0.033</radius>
          </cylinder>
        </geometry>
      </visual>
    </link>
    <joint name='right_rear_wheel_joint' type='revolute'>
      <pose relative_to='base_link'>-0.04 -0.07 0.033 0 -0 0</pose>
      <parent>base_link</parent>
      <child>right_rear_wheel_link</child>
      <axis>
        <xyz>0 1 0</xyz>
        <limit>
          <lower>-1e+16</lower>
          <upper>1e+16</upper>
        </limit>
        <dynamics>
          <spring_reference>0</spring_reference>
          <spring_stiffness>0</spring_stiffness>
        </dynamics>
      </axis>
    </joint>
    <link name='right_rear_wheel_link'>
      <pose relative_to='right_rear_wheel_joint'>0 0 0 0 -0 0</pose>
      <inertial>
        <pose>0 0 0 0 -0 0</pose>
        <mass>0.2</mass>
        <inertia>
          <ixx>5.6e-05</ixx>
          <ixy>0</ixy>
          <ixz>0</ixz>
          <iyy>5.6e-05</iyy>
          <iyz>0</iyz>
          <izz>9e-05</izz>
        </inertia>
      </inertial>
      <collision name='right_rear_wheel_link_collision'>
        <pose>0 0 0 1.5708 -0 0</pose>
        <geometry>
          <cylinder>
            <length>0.025</length>
            <radius>0.033</radius>
          </cylinder>
        </geometry>
      </collision>
      <visual name='right_rear_wheel_link_visual'>
        <pose>0 0 0 1.5708 -0 0</pose>
        <geometry>
          <cylinder>
            <length>0.025</length>
            <radius>0.033</radius>
          </cylinder>
        </geometry>
      </visual>
    </link>
    <static>0</static>
    <plugin name='gazebo_ros2_control' filename='libgazebo_ros2_control.so'>
      <ros2_control>
        <joint name='left_front_wheel_joint'/>
        <joint name='right_front_wheel_joint'/>
        <joint name='left_rear_wheel_joint'/>
        <joint name='right_rear_wheel_joint'/>
      </ros2_control>
    </plugin>
  </model>
</sdf>
