<?xml version="1.0" ?>
<!-- =================================================================================== -->
<!-- |    This document was autogenerated by xacro from /home/pi/ros2_ws_forpc/models/simple_bot.xacro | -->
<!-- |    EDITING THIS FILE BY HAND IS NOT RECOMMENDED                                 | -->
<!-- =================================================================================== -->
<robot name="simple_bot">
  <!-- ===================== Base Link ===================== -->
  <link name="base_link">
    <inertial>
      <mass value="1.0"/>
      <inertia ixx="0.001" ixy="0.0" ixz="0.0" iyy="0.001" iyz="0.0" izz="0.001"/>
    </inertial>
    <visual>
      <geometry>
        <box size="0.125 0.115 0.08"/>
      </geometry>
      <origin rpy="0 0 0" xyz="0 0 0.07300000000000001"/>
      <material name="Gray">
        <color rgba="0.6 0.6 0.6 1.0"/>
        <!-- Gazebo에서 동일하게 보이도록 추가 -->
        <ambient>0.6 0.6 0.6 1.0</ambient>
        <diffuse>0.6 0.6 0.6 1.0</diffuse>
        <specular>0.1 0.1 0.1 1.0</specular>
        <emissive>0.0 0.0 0.0 1.0</emissive>
      </material>
    </visual>
    <collision>
      <geometry>
        <box size="0.125 0.115 0.08"/>
      </geometry>
      <origin rpy="0 0 0" xyz="0 0 0.07300000000000001"/>
    </collision>
  </link>
  <!-- ===================== Wheels ===================== -->
  <!-- odom 프레임 정의 -->
  <link name="odom"/>
  <!-- odom → base_link 변환 -->
  <joint name="odom_to_base" type="fixed">
    <parent link="odom"/>
    <child link="base_link"/>
    <origin rpy="0 0 0" xyz="0 0 0"/>
  </joint>
  <link name="left_front_wheel_link">
    <inertial>
      <mass value="0.2"/>
      <inertia ixx="0.000056" ixy="0.0" ixz="0.0" iyy="0.000056" iyz="0.0" izz="0.00009"/>
    </inertial>
    <visual>
      <geometry>
        <cylinder length="0.025" radius="0.033"/>
      </geometry>
      <origin rpy="1.5708 0 0" xyz="0 0 0"/>
      <material name="Black">
        <color rgba="0 0 0 1"/>
      </material>
    </visual>
    <collision>
      <geometry>
        <cylinder length="0.025" radius="0.033"/>
      </geometry>
      <origin rpy="1.5708 0 0" xyz="0 0 0"/>
    </collision>
  </link>
  <joint name="left_front_wheel_joint" type="continuous">
    <parent link="base_link"/>
    <child link="left_front_wheel_link"/>
    <origin rpy="0 0 0" xyz="0.04 0.07 0.033"/>
    <axis xyz="0 1 0"/>
  </joint>
  <link name="left_rear_wheel_link">
    <inertial>
      <mass value="0.2"/>
      <inertia ixx="0.000056" ixy="0.0" ixz="0.0" iyy="0.000056" iyz="0.0" izz="0.00009"/>
    </inertial>
    <visual>
      <geometry>
        <cylinder length="0.025" radius="0.033"/>
      </geometry>
      <origin rpy="1.5708 0 0" xyz="0 0 0"/>
      <material name="Black">
        <color rgba="0 0 0 1"/>
      </material>
    </visual>
    <collision>
      <geometry>
        <cylinder length="0.025" radius="0.033"/>
      </geometry>
      <origin rpy="1.5708 0 0" xyz="0 0 0"/>
    </collision>
  </link>
  <joint name="left_rear_wheel_joint" type="continuous">
    <parent link="base_link"/>
    <child link="left_rear_wheel_link"/>
    <origin rpy="0 0 0" xyz="-0.04 0.07 0.033"/>
    <axis xyz="0 1 0"/>
  </joint>
  <link name="right_front_wheel_link">
    <inertial>
      <mass value="0.2"/>
      <inertia ixx="0.000056" ixy="0.0" ixz="0.0" iyy="0.000056" iyz="0.0" izz="0.00009"/>
    </inertial>
    <visual>
      <geometry>
        <cylinder length="0.025" radius="0.033"/>
      </geometry>
      <origin rpy="1.5708 0 0" xyz="0 0 0"/>
      <material name="Black">
        <color rgba="0 0 0 1"/>
      </material>
    </visual>
    <collision>
      <geometry>
        <cylinder length="0.025" radius="0.033"/>
      </geometry>
      <origin rpy="1.5708 0 0" xyz="0 0 0"/>
    </collision>
  </link>
  <joint name="right_front_wheel_joint" type="continuous">
    <parent link="base_link"/>
    <child link="right_front_wheel_link"/>
    <origin rpy="0 0 0" xyz="0.04 -0.07 0.033"/>
    <axis xyz="0 1 0"/>
  </joint>
  <link name="right_rear_wheel_link">
    <inertial>
      <mass value="0.2"/>
      <inertia ixx="0.000056" ixy="0.0" ixz="0.0" iyy="0.000056" iyz="0.0" izz="0.00009"/>
    </inertial>
    <visual>
      <geometry>
        <cylinder length="0.025" radius="0.033"/>
      </geometry>
      <origin rpy="1.5708 0 0" xyz="0 0 0"/>
      <material name="Black">
        <color rgba="0 0 0 1"/>
      </material>
    </visual>
    <collision>
      <geometry>
        <cylinder length="0.025" radius="0.033"/>
      </geometry>
      <origin rpy="1.5708 0 0" xyz="0 0 0"/>
    </collision>
  </link>
  <joint name="right_rear_wheel_joint" type="continuous">
    <parent link="base_link"/>
    <child link="right_rear_wheel_link"/>
    <origin rpy="0 0 0" xyz="-0.04 -0.07 0.033"/>
    <axis xyz="0 1 0"/>
  </joint>
  <!-- ===================== ros2_control ===================== -->
  <ros2_control name="GazeboSystem" type="system">
    <hardware>
      <plugin>gz_ros2_control/GazeboSystem</plugin>
    </hardware>
    <!-- 각 바퀴 joint 정의 -->
    <joint name="left_front_wheel_joint">
      <command_interfaces>
        <interface>velocity</interface>
      </command_interfaces>
      <state_interfaces>
        <interface>position</interface>
        <interface>velocity</interface>
      </state_interfaces>
    </joint>
    <joint name="left_rear_wheel_joint">
      <command_interfaces>
        <interface>velocity</interface>
      </command_interfaces>
      <state_interfaces>
        <interface>position</interface>
        <interface>velocity</interface>
      </state_interfaces>
    </joint>
    <joint name="right_front_wheel_joint">
      <command_interfaces>
        <interface>velocity</interface>
      </command_interfaces>
      <state_interfaces>
        <interface>position</interface>
        <interface>velocity</interface>
      </state_interfaces>
    </joint>
    <joint name="right_rear_wheel_joint">
      <command_interfaces>
        <interface>velocity</interface>
      </command_interfaces>
      <state_interfaces>
        <interface>position</interface>
        <interface>velocity</interface>
      </state_interfaces>
    </joint>
  </ros2_control>
  <!-- ===================== Ultrasonic Sensor ===================== -->
  <link name="ultrasonic_link">
    <visual>
      <geometry>
        <box size="0.02 0.05 0.02"/>
      </geometry>
      <material name="Yellow">
        <color rgba="1 1 0 1"/>
      </material>
    </visual>
  </link>
  <joint name="ultrasonic_joint" type="fixed">
    <parent link="base_link"/>
    <child link="ultrasonic_link"/>
    <origin rpy="0 0 0" xyz="0.0725 0 0.04"/>
  </joint>
  <!-- ===================== Camera ===================== -->
  <link name="camera_link">
    <visual>
      <geometry>
        <box size="0.02 0.05 0.04"/>
      </geometry>
      <material name="Red">
        <color rgba="1 0 0 1"/>
      </material>
    </visual>
  </link>
  <joint name="camera_joint" type="fixed">
    <parent link="base_link"/>
    <child link="camera_link"/>
    <origin rpy="0 0 0" xyz="0.0725 0 0.076"/>
  </joint>
  <plugin filename="libgz_ros2_control-system.so" name="gz_ros2_control">
    <parameters>/home/pi/ros2_ws_forpc/config/diff_drive_controller.yaml</parameters>
  </plugin>
</robot>
